Workbook

Sheet Guia
A1: GOAT LEAGUE · Planificación del torneo
A2: Calculadora y documentos para organizar equipos, canchas, horarios, gastos e ingresos. Imprime las hojas que necesites.
A4: CÓMO USAR ESTE ARCHIVO
A5: 1. Empieza por la hoja "Parametros": equipos por categoría, jugadores, tiempos de juego, jornada y canchas.
A6: 2. "Cronograma" arma los bloques de horario de sábado y domingo; escribe ahí los cruces de cada cancha.
A7: 3. "Canchas" calcula las horas de arriendo (incluye montaje, desmontaje y premiación). Solo pones la tarifa.
A8: 4. "Gastos" tiene todos los ítems del torneo con la cantidad ya calculada. Solo completas los precios unitarios.
A9: 5. "Ingresos" calcula utilidad, punto de equilibrio y cuota mínima por equipo. Tú defines la cuota.
A10: 6. "Cotizaciones" y "Checklist" son para imprimir y llevar a terreno.
A11: Para la fecha del 5 y 6 de diciembre, guarda una copia del archivo y cambia las fechas y parámetros.
A13: LEYENDA DE COLORES
A14: Celda para completar | B14: Amarilla con letra azul: es un dato tuyo (precio, cantidad o supuesto que puedes cambiar).
A15: Fórmula (no tocar) | B15: Blanca con letra negra: se calcula sola.
A16: Viene de otra hoja | B16: Letra verde: trae un dato desde otra hoja.
A18: EJEMPLO DE CÓMO SE COMPLETA UNA FILA DE GASTOS (no se suma)
A19: Ítem | B19: Unidad | C19: Cantidad | D19: Precio unitario | E19: Total | F19: Nota
A20: Balones N°4 (ejemplo) | B20: unidad | C20: 6 | D20: 18000 | E20: =C20*D20 -> 108000 | F20: Cantidad y precio son de ejemplo: no son cotizaciones.
A22: FORMATO DEL TORNEO (según el sitio web)
A23: Modalidad | B23: Fútbol 7, categorías Sub 7, Sub 9, Sub 11, Sub 13 y Sub 15
A24: Tiempo de juego | B24: 2 tiempos de 15 minutos
A25: Bloque por partido | B25: 45 minutos (30 de juego + transición de cancha)
A26: Jornada | B26: Sábado: fase de grupos · Domingo: semifinales, finales y premiación, de 09:00 a 12:00
A27: Fechas | B27: 1ª fecha: 7 y 8 de noviembre · Cierre de año: 5 y 6 de diciembre de 2026
A28: Premiación del sitio | B28: 180 medallas y 30 trofeos: 5 categorías × 3 puestos × 12 jugadores, y 5 × (3 copas + 3 premios individuales)

Sheet Parametros
A1: PARÁMETROS DEL TORNEO
A2: Completa las celdas amarillas. Todo lo demás (partidos, canchas, horarios y costos) se calcula solo. Los valores iniciales son un punto de partida: cámbialos.
A4: DATOS DEL TORNEO
A5: Nombre del torneo | B5: GOAT LEAGUE 2026 · Primera fecha
A6: Fecha del sábado | B6: 46333
A7: Fecha del domingo | B7: =B6+1 -> 46334
A8: Recinto / sede
A9: Cierre de inscripciones
A11: CATEGORÍAS Y EQUIPOS
A12: Categoría | B12: Equipos | C12: Grupos | D12: Equipos por grupo | E12: Jugadores por equipo | F12: Total jugadores | G12: Partidos sábado (grupos) | H12: Partidos domingo (fase final) | I12: Total partidos | J12: Reparto de grupos
A13: Sub 7 | B13: 4 | C13: 1 | D13: =IF(C13=0,0,B13/C13) -> 4 | E13: 12 | F13: =B13*E13 -> 48 | G13: =IF(C13=0,0,C13*D13*(D13-1)/2) -> 6 | H13: 2 | I13: =G13+H13 -> 8 | J13: =IF(C13=0,"Sin grupos",IF(MOD(B13,C13)=0,"OK","Revisar")) -> OK
A14: Sub 9 | B14: 4 | C14: 1 | D14: =IF(C14=0,0,B14/C14) -> 4 | E14: 12 | F14: =B14*E14 -> 48 | G14: =IF(C14=0,0,C14*D14*(D14-1)/2) -> 6 | H14: 2 | I14: =G14+H14 -> 8 | J14: =IF(C14=0,"Sin grupos",IF(MOD(B14,C14)=0,"OK","Revisar")) -> OK
A15: Sub 11 | B15: 4 | C15: 1 | D15: =IF(C15=0,0,B15/C15) -> 4 | E15: 12 | F15: =B15*E15 -> 48 | G15: =IF(C15=0,0,C15*D15*(D15-1)/2) -> 6 | H15: 2 | I15: =G15+H15 -> 8 | J15: =IF(C15=0,"Sin grupos",IF(MOD(B15,C15)=0,"OK","Revisar")) -> OK
A16: Sub 13 | B16: 4 | C16: 1 | D16: =IF(C16=0,0,B16/C16) -> 4 | E16: 12 | F16: =B16*E16 -> 48 | G16: =IF(C16=0,0,C16*D16*(D16-1)/2) -> 6 | H16: 2 | I16: =G16+H16 -> 8 | J16: =IF(C16=0,"Sin grupos",IF(MOD(B16,C16)=0,"OK","Revisar")) -> OK
A17: Sub 15 | B17: 4 | C17: 1 | D17: =IF(C17=0,0,B17/C17) -> 4 | E17: 12 | F17: =B17*E17 -> 48 | G17: =IF(C17=0,0,C17*D17*(D17-1)/2) -> 6 | H17: 2 | I17: =G17+H17 -> 8 | J17: =IF(C17=0,"Sin grupos",IF(MOD(B17,C17)=0,"OK","Revisar")) -> OK
A18: TOTAL | B18: =SUM(B13:B17) -> 20 | C18: =SUM(C13:C17) -> 5 | F18: =SUM(F13:F17) -> 240 | G18: =SUM(G13:G17) -> 30 | H18: =SUM(H13:H17) -> 10 | I18: =SUM(I13:I17) -> 40
A19: Grupos: todos juegan contra todos dentro de su grupo (sábado). Partidos del domingo = semifinales + final + tercer lugar que definas por categoría (ej.: 2 grupos → 4 partidos; 1 grupo de 4 → 2 partidos: final y tercer lugar).
A21: TIEMPOS DE JUEGO
A22: Duración de cada tiempo (min) | B22: 15
A23: Cantidad de tiempos | B23: 2
A24: Minutos de juego por partido | B24: =B22*B23 -> 30
A25: Bloque total por partido (min) | B25: 45 | C25: Incluye juego, entretiempo y transición de cancha.
A26: Minutos de descanso y transición por partido | B26: =B25-B24 -> 15 | C26: Si es negativo, el bloque es menor que el juego.
A28: JORNADA Y CANCHAS
A29: Hora de inicio de partidos | B29: 0.375 | C29: Igual los dos días.
A30: Hora de término prevista de la jornada | B30: 0.5 | C30: Según el sitio: 09:00 a 12:00.
A31: Horas de juego por día | B31: =(B30-B29)*24 -> 3
A32: Bloques de partido por cancha por día | B32: =INT(ROUND((B30-B29)*1440,0)/B25) -> 4 | C32: Cuántos partidos caben en una cancha en la jornada.
A33: Canchas simultáneas que usarás | B33: 8 | C33: Cambia este número y mira el estado de la jornada (B46).
A34: Partidos que caben el sábado | B34: =B32*B33 -> 32
A35: Partidos que caben el domingo | B35: =B32*B33 -> 32
A36: Partidos necesarios el sábado | B36: =G18 -> 30
A37: Partidos necesarios el domingo | B37: =H18 -> 10
A38: Canchas necesarias para cumplir la jornada (sábado) | B38: =IF(B32=0,0,ROUNDUP(B36/B32,0)) -> 8 | C38: Con la jornada y el bloque definidos arriba.
A39: Canchas necesarias para cumplir la jornada (domingo) | B39: =IF(B32=0,0,ROUNDUP(B37/B32,0)) -> 3
A40: Bloques que necesitas por cancha (sábado) | B40: =IF(B33=0,0,ROUNDUP(B36/B33,0)) -> 4 | C40: Con las canchas que elegiste.
A41: Bloques que necesitas por cancha (domingo) | B41: =IF(B33=0,0,ROUNDUP(B37/B33,0)) -> 2
A42: Hora de término de partidos del sábado | B42: =B29+B40*B25/1440 -> 0.5
A43: Hora de término de partidos del domingo | B43: =B29+B41*B25/1440 -> 0.4375 | C43: La premiación va después de esta hora.
A44: Horas de juego necesarias el sábado | B44: =B40*B25/60 -> 3
...

Sheet Cronograma
A1: CRONOGRAMA DE PARTIDOS
A2: Los horarios salen de la hoja Parametros. Escribe en cada cancha el cruce (ej.: "Club A vs Club B · Sub 9"). Las canchas que no usas aparecen con "—".
A4: SÁBADO · FASE DE GRUPOS | D4: =Parametros!B6 -> 46333
A5: Bloque | B5: Inicio | C5: Fin | D5: =IF(1<=Parametros!$B$33,"Cancha 1","") -> Cancha 1 | E5: =IF(2<=Parametros!$B$33,"Cancha 2","") -> Cancha 2 | F5: =IF(3<=Parametros!$B$33,"Cancha 3","") -> Cancha 3 | G5: =IF(4<=Parametros!$B$33,"Cancha 4","") -> Cancha 4 | H5: =IF(5<=Parametros!$B$33,"Cancha 5","") -> Cancha 5 | I5: =IF(6<=Parametros!$B$33,"Cancha 6","") -> Cancha 6 | J5: =IF(7<=Parametros!$B$33,"Cancha 7","") -> Cancha 7 | K5: =IF(8<=Parametros!$B$33,"Cancha 8","") -> Cancha 8 | L5: =IF(9<=Parametros!$B$33,"Cancha 9","") | M5: =IF(10<=Parametros!$B$33,"Cancha 10","") | N5: Se usa
A6: 1 | B6: =Parametros!$B$29+(1-1)*Parametros!$B$25/1440 -> 0.375 | C6: =B6+Parametros!$B$25/1440 -> 0.40625 | D6: =IF(1>Parametros!$B$33,"—","") | E6: =IF(2>Parametros!$B$33,"—","") | F6: =IF(3>Parametros!$B$33,"—","") | G6: =IF(4>Parametros!$B$33,"—","") | H6: =IF(5>Parametros!$B$33,"—","") | I6: =IF(6>Parametros!$B$33,"—","") | J6: =IF(7>Parametros!$B$33,"—","") | K6: =IF(8>Parametros!$B$33,"—","") | L6: =IF(9>Parametros!$B$33,"—","") -> — | M6: =IF(10>Parametros!$B$33,"—","") -> — | N6: =IF(1<=Parametros!$B$40,"Sí","libre") -> Sí
A7: 2 | B7: =Parametros!$B$29+(2-1)*Parametros!$B$25/1440 -> 0.40625 | C7: =B7+Parametros!$B$25/1440 -> 0.4375 | D7: =IF(1>Parametros!$B$33,"—","") | E7: =IF(2>Parametros!$B$33,"—","") | F7: =IF(3>Parametros!$B$33,"—","") | G7: =IF(4>Parametros!$B$33,"—","") | H7: =IF(5>Parametros!$B$33,"—","") | I7: =IF(6>Parametros!$B$33,"—","") | J7: =IF(7>Parametros!$B$33,"—","") | K7: =IF(8>Parametros!$B$33,"—","") | L7: =IF(9>Parametros!$B$33,"—","") -> — | M7: =IF(10>Parametros!$B$33,"—","") -> — | N7: =IF(2<=Parametros!$B$40,"Sí","libre") -> Sí
A8: 3 | B8: =Parametros!$B$29+(3-1)*Parametros!$B$25/1440 -> 0.4375 | C8: =B8+Parametros!$B$25/1440 -> 0.46875 | D8: =IF(1>Parametros!$B$33,"—","") | E8: =IF(2>Parametros!$B$33,"—","") | F8: =IF(3>Parametros!$B$33,"—","") | G8: =IF(4>Parametros!$B$33,"—","") | H8: =IF(5>Parametros!$B$33,"—","") | I8: =IF(6>Parametros!$B$33,"—","") | J8: =IF(7>Parametros!$B$33,"—","") | K8: =IF(8>Parametros!$B$33,"—","") | L8: =IF(9>Parametros!$B$33,"—","") -> — | M8: =IF(10>Parametros!$B$33,"—","") -> — | N8: =IF(3<=Parametros!$B$40,"Sí","libre") -> Sí
A9: 4 | B9: =Parametros!$B$29+(4-1)*Parametros!$B$25/1440 -> 0.46875 | C9: =B9+Parametros!$B$25/1440 -> 0.5 | D9: =IF(1>Parametros!$B$33,"—","") | E9: =IF(2>Parametros!$B$33,"—","") | F9: =IF(3>Parametros!$B$33,"—","") | G9: =IF(4>Parametros!$B$33,"—","") | H9: =IF(5>Parametros!$B$33,"—","") | I9: =IF(6>Parametros!$B$33,"—","") | J9: =IF(7>Parametros!$B$33,"—","") | K9: =IF(8>Parametros!$B$33,"—","") | L9: =IF(9>Parametros!$B$33,"—","") -> — | M9: =IF(10>Parametros!$B$33,"—","") -> — | N9: =IF(4<=Parametros!$B$40,"Sí","libre") -> Sí
A10: 5 | B10: =Parametros!$B$29+(5-1)*Parametros!$B$25/1440 -> 0.5 | C10: =B10+Parametros!$B$25/1440 -> 0.53125 | D10: =IF(1>Parametros!$B$33,"—","") | E10: =IF(2>Parametros!$B$33,"—","") | F10: =IF(3>Parametros!$B$33,"—","") | G10: =IF(4>Parametros!$B$33,"—","") | H10: =IF(5>Parametros!$B$33,"—","") | I10: =IF(6>Parametros!$B$33,"—","") | J10: =IF(7>Parametros!$B$33,"—","") | K10: =IF(8>Parametros!$B$33,"—","") | L10: =IF(9>Parametros!$B$33,"—","") -> — | M10: =IF(10>Parametros!$B$33,"—","") -> — | N10: =IF(5<=Parametros!$B$40,"Sí","libre") -> libre
A11: 6 | B11: =Parametros!$B$29+(6-1)*Parametros!$B$25/1440 -> 0.53125 | C11: =B11+Parametros!$B$25/1440 -> 0.5625 | D11: =IF(1>Parametros!$B$33,"—","") | E11: =IF(2>Parametros!$B$33,"—","") | F11: =IF(3>Parametros!$B$33,"—","") | G11: =IF(4>Parametros!$B$33,"—","") | H11: =IF(5>Parametros!$B$33,"—","") | I11: =IF(6>Parametros!$B$33,"—","") | J11: =IF(7>Parametros!$B$33,"—","") | K11: =IF(8>Parametros!$B$33,"—","") | L11: =IF(9>Parametros!$B$33,"—","") -> — | M11: =IF(10>Parametros!$B$33,"—","") -> — | N11: =IF(6<=Parametros!$B$40,"Sí","libre") -> libre
A12: 7 | B12: =Parametros!$B$29+(7-1)*Parametros!$B$25/1440 -> 0.5625 | C12: =B12+Parametros!$B$25/1440 -> 0.59375 | D12: =IF(1>Parametros!$B$33,"—","") | E12: =IF(2>Parametros!$B$33,"—","") | F12: =IF(3>Parametros!$B$33,"—","") | G12: =IF(4>Parametros!$B$33,"—","") | H12: =IF(5>Parametros!$B$33,"—","") | I12: =IF(6>Parametros!$B$33,"—","") | J12: =IF(7>Parametros!$B$33,"—","") | K12: =IF(8>Parametros!$B$33,"—","") | L12: =IF(9>Parametros!$B$33,"—","") -> — | M12: =IF(10>Parametros!$B$33,"—","") -> — | N12: =IF(7<=Parametros!$B$40,"Sí","libre") -> libre
A13: 8 | B13: =Parametros!$B$29+(8-1)*Parametros!$B$25/1440 -> 0.59375 | C13: =B13+Parametros!$B$25/1440 -> 0.625 | D13: =IF(1>Parametros!$B$33,"—","") | E13: =IF(2>Parametros!$B$33,"—","") | F13: =IF(3>Parametros!$B$33,"—","") | G13: =IF(4>Parametros!$B$33,"—","") | H13: =IF(5>Parametros!$B$33,"—","") | I13: =IF(6>Parametros!$B$33,"—","") | J13: =IF(7>Parametros!$B$33,"—","") | K13: =IF(8>Parametros!$B$33,"—","") | L13: =IF(9>Parametros!$B$33,"—","") -> — | M13: =IF(10>Parametros!$B$33,"—","") -> — | N13: =IF(8<=Parametros!$B$40,"Sí","libre") -> libre
A14: 9 | B14: =Parametros!$B$29+(9-1)*Parametros!$B$25/1440 -> 0.625 | C14: =B14+Parametros!$B$25/1440 -> 0.65625 | D14: =IF(1>Parametros!$B$33,"—","") | E14: =IF(2>Parametros!$B$33,"—","") | F14: =IF(3>Parametros!$B$33,"—","") | G14: =IF(4>Parametros!$B$33,"—","") | H14: =IF(5>Parametros!$B$33,"—","") | I14: =IF(6>Parametros!$B$33,"—","") | J14: =IF(7>Parametros!$B$33,"—","") | K14: =IF(8>Parametros!$B$33,"—","") | L14: =IF(9>Parametros!$B$33,"—","") -> — | M14: =IF(10>Parametros!$B$33,"—","") -> — | N14: =IF(9<=Parametros!$B$40,"Sí","libre") -> libre
A15: 10 | B15: =Parametros!$B$29+(10-1)*Parametros!$B$25/1440 -> 0.65625 | C15: =B15+Parametros!$B$25/1440 -> 0.6875 | D15: =IF(1>Parametros!$B$33,"—","") | E15: =IF(2>Parametros!$B$33,"—","") | F15: =IF(3>Parametros!$B$33,"—","") | G15: =IF(4>Parametros!$B$33,"—","") | H15: =IF(5>Parametros!$B$33,"—","") | I15: =IF(6>Parametros!$B$33,"—","") | J15: =IF(7>Parametros!$B$33,"—","") | K15: =IF(8>Parametros!$B$33,"—","") | L15: =IF(9>Parametros!$B$33,"—","") -> — | M15: =IF(10>Parametros!$B$33,"—","") -> — | N15: =IF(10<=Parametros!$B$40,"Sí","libre") -> libre
A16: 11 | B16: =Parametros!$B$29+(11-1)*Parametros!$B$25/1440 -> 0.6875 | C16: =B16+Parametros!$B$25/1440 -> 0.71875 | D16: =IF(1>Parametros!$B$33,"—","") | E16: =IF(2>Parametros!$B$33,"—","") | F16: =IF(3>Parametros!$B$33,"—","") | G16: =IF(4>Parametros!$B$33,"—","") | H16: =IF(5>Parametros!$B$33,"—","") | I16: =IF(6>Parametros!$B$33,"—","") | J16: =IF(7>Parametros!$B$33,"—","") | K16: =IF(8>Parametros!$B$33,"—","") | L16: =IF(9>Parametros!$B$33,"—","") -> — | M16: =IF(10>Parametros!$B$33,"—","") -> — | N16: =IF(11<=Parametros!$B$40,"Sí","libre") -> libre
A17: 12 | B17: =Parametros!$B$29+(12-1)*Parametros!$B$25/1440 -> 0.71875 | C17: =B17+Parametros!$B$25/1440 -> 0.75 | D17: =IF(1>Parametros!$B$33,"—","") | E17: =IF(2>Parametros!$B$33,"—","") | F17: =IF(3>Parametros!$B$33,"—","") | G17: =IF(4>Parametros!$B$33,"—","") | H17: =IF(5>Parametros!$B$33,"—","") | I17: =IF(6>Parametros!$B$33,"—","") | J17: =IF(7>Parametros!$B$33,"—","") | K17: =IF(8>Parametros!$B$33,"—","") | L17: =IF(9>Parametros!$B$33,"—","") -> — | M17: =IF(10>Parametros!$B$33,"—","") -> — | N17: =IF(12<=Parametros!$B$40,"Sí","libre") -> libre
A18: Término de partidos: | D18: =Parametros!B42 -> 0.5
A20: DOMINGO · SEMIFINALES, FINALES Y PREMIACIÓN | D20: =Parametros!B7 -> 46334
A21: Bloque | B21: Inicio | C21: Fin | D21: =IF(1<=Parametros!$B$33,"Cancha 1","") -> Cancha 1 | E21: =IF(2<=Parametros!$B$33,"Cancha 2","") -> Cancha 2 | F21: =IF(3<=Parametros!$B$33,"Cancha 3","") -> Cancha 3 | G21: =IF(4<=Parametros!$B$33,"Cancha 4","") -> Cancha 4 | H21: =IF(5<=Parametros!$B$33,"Cancha 5","") -> Cancha 5 | I21: =IF(6<=Parametros!$B$33,"Cancha 6","") -> Cancha 6 | J21: =IF(7<=Parametros!$B$33,"Cancha 7","") -> Cancha 7 | K21: =IF(8<=Parametros!$B$33,"Cancha 8","") -> Cancha 8 | L21: =IF(9<=Parametros!$B$33,"Cancha 9","") | M21: =IF(10<=Parametros!$B$33,"Cancha 10","") | N21: Se usa
A22: 1 | B22: =Parametros!$B$29+(1-1)*Parametros!$B$25/1440 -> 0.375 | C22: =B22+Parametros!$B$25/1440 -> 0.40625 | D22: =IF(1>Parametros!$B$33,"—","") | E22: =IF(2>Parametros!$B$33,"—","") | F22: =IF(3>Parametros!$B$33,"—","") | G22: =IF(4>Parametros!$B$33,"—","") | H22: =IF(5>Parametros!$B$33,"—","") | I22: =IF(6>Parametros!$B$33,"—","") | J22: =IF(7>Parametros!$B$33,"—","") | K22: =IF(8>Parametros!$B$33,"—","") | L22: =IF(9>Parametros!$B$33,"—","") -> — | M22: =IF(10>Parametros!$B$33,"—","") -> — | N22: =IF(1<=Parametros!$B$41,"Sí","libre") -> Sí
A23: 2 | B23: =Parametros!$B$29+(2-1)*Parametros!$B$25/1440 -> 0.40625 | C23: =B23+Parametros!$B$25/1440 -> 0.4375 | D23: =IF(1>Parametros!$B$33,"—","") | E23: =IF(2>Parametros!$B$33,"—","") | F23: =IF(3>Parametros!$B$33,"—","") | G23: =IF(4>Parametros!$B$33,"—","") | H23: =IF(5>Parametros!$B$33,"—","") | I23: =IF(6>Parametros!$B$33,"—","") | J23: =IF(7>Parametros!$B$33,"—","") | K23: =IF(8>Parametros!$B$33,"—","") | L23: =IF(9>Parametros!$B$33,"—","") -> — | M23: =IF(10>Parametros!$B$33,"—","") -> — | N23: =IF(2<=Parametros!$B$41,"Sí","libre") -> Sí
A24: 3 | B24: =Parametros!$B$29+(3-1)*Parametros!$B$25/1440 -> 0.4375 | C24: =B24+Parametros!$B$25/1440 -> 0.46875 | D24: =IF(1>Parametros!$B$33,"—","") | E24: =IF(2>Parametros!$B$33,"—","") | F24: =IF(3>Parametros!$B$33,"—","") | G24: =IF(4>Parametros!$B$33,"—","") | H24: =IF(5>Parametros!$B$33,"—","") | I24: =IF(6>Parametros!$B$33,"—","") | J24: =IF(7>Parametros!$B$33,"—","") | K24: =IF(8>Parametros!$B$33,"—","") | L24: =IF(9>Parametros!$B$33,"—","") -> — | M24: =IF(10>Parametros!$B$33,"—","") -> — | N24: =IF(3<=Parametros!$B$41,"Sí","libre") -> libre
A25: 4 | B25: =Parametros!$B$29+(4-1)*Parametros!$B$25/1440 -> 0.46875 | C25: =B25+Parametros!$B$25/1440 -> 0.5 | D25: =IF(1>Parametros!$B$33,"—","") | E25: =IF(2>Parametros!$B$33,"—","") | F25: =IF(3>Parametros!$B$33,"—","") | G25: =IF(4>Parametros!$B$33,"—","") | H25: =IF(5>Parametros!$B$33,"—","") | I25: =IF(6>Parametros!$B$33,"—","") | J25: =IF(7>Parametros!$B$33,"—","") | K25: =IF(8>Parametros!$B$33,"—","") | L25: =IF(9>Parametros!$B$33,"—","") -> — | M25: =IF(10>Parametros!$B$33,"—","") -> — | N25: =IF(4<=Parametros!$B$41,"Sí","libre") -> libre
A26: 5 | B26: =Parametros!$B$29+(5-1)*Parametros!$B$25/1440 -> 0.5 | C26: =B26+Parametros!$B$25/1440 -> 0.53125 | D26: =IF(1>Parametros!$B$33,"—","") | E26: =IF(2>Parametros!$B$33,"—","") | F26: =IF(3>Parametros!$B$33,"—","") | G26: =IF(4>Parametros!$B$33,"—","") | H26: =IF(5>Parametros!$B$33,"—","") | I26: =IF(6>Parametros!$B$33,"—","") | J26: =IF(7>Parametros!$B$33,"—","") | K26: =IF(8>Parametros!$B$33,"—","") | L26: =IF(9>Parametros!$B$33,"—","") -> — | M26: =IF(10>Parametros!$B$33,"—","") -> — | N26: =IF(5<=Parametros!$B$41,"Sí","libre") -> libre
A27: 6 | B27: =Parametros!$B$29+(6-1)*Parametros!$B$25/1440 -> 0.53125 | C27: =B27+Parametros!$B$25/1440 -> 0.5625 | D27: =IF(1>Parametros!$B$33,"—","") | E27: =IF(2>Parametros!$B$33,"—","") | F27: =IF(3>Parametros!$B$33,"—","") | G27: =IF(4>Parametros!$B$33,"—","") | H27: =IF(5>Parametros!$B$33,"—","") | I27: =IF(6>Parametros!$B$33,"—","") | J27: =IF(7>Parametros!$B$33,"—","") | K27: =IF(8>Parametros!$B$33,"—","") | L27: =IF(9>Parametros!$B$33,"—","") -> — | M27: =IF(10>Parametros!$B$33,"—","") -> — | N27: =IF(6<=Parametros!$B$41,"Sí","libre") -> libre
A28: 7 | B28: =Parametros!$B$29+(7-1)*Parametros!$B$25/1440 -> 0.5625 | C28: =B28+Parametros!$B$25/1440 -> 0.59375 | D28: =IF(1>Parametros!$B$33,"—","") | E28: =IF(2>Parametros!$B$33,"—","") | F28: =IF(3>Parametros!$B$33,"—","") | G28: =IF(4>Parametros!$B$33,"—","") | H28: =IF(5>Parametros!$B$33,"—","") | I28: =IF(6>Parametros!$B$33,"—","") | J28: =IF(7>Parametros!$B$33,"—","") | K28: =IF(8>Parametros!$B$33,"—","") | L28: =IF(9>Parametros!$B$33,"—","") -> — | M28: =IF(10>Parametros!$B$33,"—","") -> — | N28: =IF(7<=Parametros!$B$41,"Sí","libre") -> libre
A29: 8 | B29: =Parametros!$B$29+(8-1)*Parametros!$B$25/1440 -> 0.59375 | C29: =B29+Parametros!$B$25/1440 -> 0.625 | D29: =IF(1>Parametros!$B$33,"—","") | E29: =IF(2>Parametros!$B$33,"—","") | F29: =IF(3>Parametros!$B$33,"—","") | G29: =IF(4>Parametros!$B$33,"—","") | H29: =IF(5>Parametros!$B$33,"—","") | I29: =IF(6>Parametros!$B$33,"—","") | J29: =IF(7>Parametros!$B$33,"—","") | K29: =IF(8>Parametros!$B$33,"—","") | L29: =IF(9>Parametros!$B$33,"—","") -> — | M29: =IF(10>Parametros!$B$33,"—","") -> — | N29: =IF(8<=Parametros!$B$41,"Sí","libre") -> libre
A30: 9 | B30: =Parametros!$B$29+(9-1)*Parametros!$B$25/1440 -> 0.625 | C30: =B30+Parametros!$B$25/1440 -> 0.65625 | D30: =IF(1>Parametros!$B$33,"—","") | E30: =IF(2>Parametros!$B$33,"—","") | F30: =IF(3>Parametros!$B$33,"—","") | G30: =IF(4>Parametros!$B$33,"—","") | H30: =IF(5>Parametros!$B$33,"—","") | I30: =IF(6>Parametros!$B$33,"—","") | J30: =IF(7>Parametros!$B$33,"—","") | K30: =IF(8>Parametros!$B$33,"—","") | L30: =IF(9>Parametros!$B$33,"—","") -> — | M30: =IF(10>Parametros!$B$33,"—","") -> — | N30: =IF(9<=Parametros!$B$41,"Sí","libre") -> libre
A31: 10 | B31: =Parametros!$B$29+(10-1)*Parametros!$B$25/1440 -> 0.65625 | C31: =B31+Parametros!$B$25/1440 -> 0.6875 | D31: =IF(1>Parametros!$B$33,"—","") | E31: =IF(2>Parametros!$B$33,"—","") | F31: =IF(3>Parametros!$B$33,"—","") | G31: =IF(4>Parametros!$B$33,"—","") | H31: =IF(5>Parametros!$B$33,"—","") | I31: =IF(6>Parametros!$B$33,"—","") | J31: =IF(7>Parametros!$B$33,"—","") | K31: =IF(8>Parametros!$B$33,"—","") | L31: =IF(9>Parametros!$B$33,"—","") -> — | M31: =IF(10>Parametros!$B$33,"—","") -> — | N31: =IF(10<=Parametros!$B$41,"Sí","libre") -> libre
A32: 11 | B32: =Parametros!$B$29+(11-1)*Parametros!$B$25/1440 -> 0.6875 | C32: =B32+Parametros!$B$25/1440 -> 0.71875 | D32: =IF(1>Parametros!$B$33,"—","") | E32: =IF(2>Parametros!$B$33,"—","") | F32: =IF(3>Parametros!$B$33,"—","") | G32: =IF(4>Parametros!$B$33,"—","") | H32: =IF(5>Parametros!$B$33,"—","") | I32: =IF(6>Parametros!$B$33,"—","") | J32: =IF(7>Parametros!$B$33,"—","") | K32: =IF(8>Parametros!$B$33,"—","") | L32: =IF(9>Parametros!$B$33,"—","") -> — | M32: =IF(10>Parametros!$B$33,"—","") -> — | N32: =IF(11<=Parametros!$B$41,"Sí","libre") -> libre
A33: 12 | B33: =Parametros!$B$29+(12-1)*Parametros!$B$25/1440 -> 0.71875 | C33: =B33+Parametros!$B$25/1440 -> 0.75 | D33: =IF(1>Parametros!$B$33,"—","") | E33: =IF(2>Parametros!$B$33,"—","") | F33: =IF(3>Parametros!$B$33,"—","") | G33: =IF(4>Parametros!$B$33,"—","") | H33: =IF(5>Parametros!$B$33,"—","") | I33: =IF(6>Parametros!$B$33,"—","") | J33: =IF(7>Parametros!$B$33,"—","") | K33: =IF(8>Parametros!$B$33,"—","") | L33: =IF(9>Parametros!$B$33,"—","") -> — | M33: =IF(10>Parametros!$B$33,"—","") -> — | N33: =IF(12<=Parametros!$B$41,"Sí","libre") -> libre
A34: Término de partidos: | D34: =Parametros!B43 -> 0.4375
A35: Premiación y cierre: | D35: =D34 -> 0.4375 | E35: =D35+Parametros!B49/1440 -> 0.45833333 | F35: inicio → fin
A37: Regla sugerida: ningún equipo juega dos bloques seguidos y cada equipo descansa al menos un bloque entre partidos. Si el estado de la jornada en Parametros dice "NO CABE", las filas "Fuera" no caben en el horario definido.

Sheet Canchas
A1: ARRIENDO DE CANCHAS
A2: Las horas salen del cronograma: horas de partidos + montaje + premiación + desmontaje. Solo debes poner la tarifa que te cobre el recinto.
A4: Concepto | B4: Sábado | C4: Domingo | D4: Nota
A5: Canchas a arrendar | B5: =Parametros!B33 -> 8 | C5: =Parametros!B33 -> 8
A6: Hora de inicio de partidos | B6: =Parametros!B29 -> 0.375 | C6: =Parametros!B29 -> 0.375
A7: Hora de término de partidos | B7: =Parametros!B42 -> 0.5 | C7: =Parametros!B43 -> 0.4375
A8: Premiación y cierre (min) | B8: 0 | C8: =Parametros!B49 -> 30 | D8: Solo el domingo.
A9: Montaje antes (min) | B9: =Parametros!B50 -> 60 | C9: =Parametros!B50 -> 60
A10: Desmontaje después (min) | B10: =Parametros!B51 -> 60 | C10: =Parametros!B51 -> 60
A11: Horas totales de arriendo por cancha | B11: =ROUND(((B7-B6)*1440+B8+B9+B10)/60,2) -> 5 | C11: =ROUND(((C7-C6)*1440+C8+C9+C10)/60,2) -> 4 | D11: Es lo que paga cada cancha ese día.
A12: Tarifa por hora por cancha (CLP) | D12: Pon aquí lo que cobra el recinto por hora.
A13: Tarifa fija por día por cancha (CLP) | D13: Solo si el recinto cobra por día completo. Si la completas, reemplaza la tarifa por hora.
A14: COSTO DE ARRIENDO DEL DÍA | B14: =IF(B13>0,B5*B13,B5*B11*B12) -> 0 | C14: =IF(C13>0,C5*C13,C5*C11*C12) -> 0
A15: TOTAL ARRIENDO DE CANCHAS | B15: =B14+C14 -> 0
A17: Horas pagadas que no son de juego (montaje, desmontaje y premiación) | B17: =B11-(B7-B6)*24 -> 2 | C17: =C11-(C7-C6)*24 -> 2.5 | D17: Negocia estas horas con el recinto: son las que más puedes reducir.

Sheet Gastos
A1: GASTOS DEL TORNEO
A2: Solo completa los precios unitarios (celdas amarillas de la columna D). Las cantidades vienen calculadas desde Parametros: puedes sobrescribirlas.
A3: Ítem | B3: Unidad | C3: Cantidad | D3: Precio unitario (CLP) | E3: Total (CLP) | F3: Cómo se calculó la cantidad / notas
A4: 1. ARRIENDO DE CANCHAS Y RECINTO
A5: Arriendo de canchas · sábado | B5: día | C5: 1 | E5: =Canchas!B14 -> 0 | F5: Calculado en la hoja Canchas
A6: Arriendo de canchas · domingo | B6: día | C6: 1 | E6: =Canchas!C14 -> 0 | F6: Calculado en la hoja Canchas
A7: Camarines, baños e iluminación (si se cobran aparte) | B7: día | C7: 2 | E7: =C7*D7 -> 0
A8: Subtotal Arriendo De Canchas Y Recinto | E8: =SUM(E5:E7) -> 0
A10: 2. PREMIACIÓN
A11: Copas campeón (grande) | B11: unidad | C11: =COUNTA(Parametros!$A$13:$A$17) -> 5 | E11: =C11*D11 -> 0 | F11: Una por categoría.
A12: Copas subcampeón (mediana) | B12: unidad | C12: =COUNTA(Parametros!$A$13:$A$17) -> 5 | E12: =C12*D12 -> 0 | F12: Una por categoría.
A13: Copas tercer lugar | B13: unidad | C13: =COUNTA(Parametros!$A$13:$A$17) -> 5 | E13: =C13*D13 -> 0 | F13: Una por categoría.
A14: Medallas de oro | B14: unidad | C14: =COUNTA(Parametros!$A$13:$A$17)*Parametros!$B$52 -> 60 | E14: =C14*D14 -> 0 | F14: Categorías × jugadores por equipo con medalla.
A15: Medallas de plata | B15: unidad | C15: =COUNTA(Parametros!$A$13:$A$17)*Parametros!$B$52 -> 60 | E15: =C15*D15 -> 0 | F15: Ídem.
A16: Medallas de bronce | B16: unidad | C16: =COUNTA(Parametros!$A$13:$A$17)*Parametros!$B$52 -> 60 | E16: =C16*D16 -> 0 | F16: Ídem.
A17: Trofeo Botín de Oro | B17: unidad | C17: =COUNTA(Parametros!$A$13:$A$17) -> 5 | E17: =C17*D17 -> 0 | F17: Uno por categoría.
A18: Trofeo Guante de Oro | B18: unidad | C18: =COUNTA(Parametros!$A$13:$A$17) -> 5 | E18: =C18*D18 -> 0 | F18: Uno por categoría.
A19: Trofeo MVP · GOAT | B19: unidad | C19: =COUNTA(Parametros!$A$13:$A$17) -> 5 | E19: =C19*D19 -> 0 | F19: Uno por categoría.
A20: Reconocimiento de participación (diploma o medalla) | B20: unidad | C20: =MAX(0,Parametros!$F$18-COUNTA(Parametros!$A$13:$A$17)*Parametros!$B$52*3) -> 60 | E20: =C20*D20 -> 0 | F20: Jugadores que no reciben medalla de podio.
A21: Premio Fair Play (copa especial) | B21: unidad | C21: 1 | E21: =C21*D21 -> 0 | F21: Opcional.
A22: Podio / tarima de premiación (arriendo) | B22: unidad | C22: 1 | E22: =C22*D22 -> 0
A23: Subtotal Premiación | E23: =SUM(E11:E22) -> 0
A25: 3. EQUIPAMIENTO DEPORTIVO
A26: Balones N°3 (Sub 7 y Sub 9) | B26: unidad | C26: =Parametros!$B$33+1 -> 9 | E26: =C26*D26 -> 0 | F26: Uno por cancha + 1 de reserva.
A27: Balones N°4 (Sub 11 y Sub 13) | B27: unidad | C27: =Parametros!$B$33+1 -> 9 | E27: =C27*D27 -> 0 | F27: Uno por cancha + 1 de reserva.
A28: Balones N°5 (Sub 15) | B28: unidad | C28: =Parametros!$B$33+1 -> 9 | E28: =C28*D28 -> 0 | F28: Uno por cancha + 1 de reserva.
A29: Petos (2 colores) | B29: unidad | C29: =Parametros!$B$33*16 -> 128 | E29: =C29*D29 -> 0 | F29: 16 por cancha: 8 de cada color.
A30: Conos / platillos (set) | B30: set | C30: =Parametros!$B$33 -> 8 | E30: =C30*D30 -> 0 | F30: Un set por cancha.
A31: Arcos de fútbol 7 (arriendo, si el recinto no los tiene) | B31: unidad | C31: =Parametros!$B$33*2 -> 16 | E31: =C31*D31 -> 0 | F31: Dos por cancha.
A32: Redes de repuesto | B32: unidad | C32: 4 | E32: =C32*D32 -> 0
A33: Banderines de córner (juego de 4) | B33: juego | C33: =Parametros!$B$33 -> 8 | E33: =C33*D33 -> 0 | F33: Un juego por cancha.
A34: Bombas de aire, agujas y cinta | B34: set | C34: 2 | E34: =C34*D34 -> 0
A35: Subtotal Equipamiento Deportivo | E35: =SUM(E26:E34) -> 0
A37: 4. ARBITRAJE Y MESA DE CONTROL
A38: Árbitro central (pago por jornada) | B38: jornada | C38: =Parametros!$B$33*Parametros!$B$55 -> 16 | E38: =C38*D38 -> 0 | F38: Canchas × días. Si pagas por partido, deja 0 y usa la fila de abajo.
A39: Árbitro asistente (pago por jornada) | B39: jornada | C39: 0 | E39: =C39*D39 -> 0 | F39: Opcional.
A40: Árbitros pagados por partido (alternativa) | B40: partido | C40: 0 | E40: =C40*D40 -> 0 | F40: Si pagas por partido, escribe aquí el total de partidos (Parametros!I18) y deja las jornadas en 0.
A41: Planilleros / mesa de control | B41: jornada | C41: 4 | E41: =C41*D41 -> 0 | F41: 2 personas por día.
A42: Coordinador de árbitros | B42: jornada | C42: 2 | E42: =C42*D42 -> 0 | F42: Uno por día.
A43: Subtotal Arbitraje Y Mesa De Control | E43: =SUM(E38:E42) -> 0
...

Sheet Ingresos
A1: INGRESOS, UTILIDAD Y PUNTO DE EQUILIBRIO
A2: Define la cuota por equipo y mira cuánto necesitas recaudar. Los gastos vienen de la hoja Gastos.
A4: INGRESOS
A5: Equipos inscritos (hoja Parametros) | B5: =Parametros!B18 -> 20
A6: Cuota de inscripción por equipo (CLP)
A7: Descuento promedio por pronto pago o convenio (%)
A8: Ingreso por inscripciones | B8: =B5*B6*(1-B7) -> 0
A9: Auspicios y patrocinios
A10: Cantina / food trucks (arriendo o venta)
A11: Otros (fotos, merchandising)
A12: TOTAL INGRESOS BRUTOS | B12: =SUM(B8:B11) -> 0
A13: Comisión de pasarela de pago (% sobre inscripciones)
A14: Impuestos (IVA / retención, % sobre ingresos)
A15: Descuento por comisión e impuestos | B15: =B8*B13+B12*B14 -> 0
A16: INGRESOS NETOS | B16: =B12-B15 -> 0
A18: RESULTADO
A19: Total gastos (hoja Gastos) | B19: =Gastos!E98 -> 0
A20: UTILIDAD O PÉRDIDA | B20: =B16-B19 -> 0
A21: Margen sobre ingresos brutos | B21: =IF(B12=0,0,B20/B12) -> 0
A23: COSTO POR UNIDAD
A24: Costo por equipo | B24: =IF(B5=0,0,B19/B5) -> 0
A25: Costo por jugador | B25: =IF(Parametros!F18=0,0,B19/Parametros!F18) -> 0
A26: Costo por partido | B26: =IF(Parametros!I18=0,0,B19/Parametros!I18) -> 0
A27: Cuota equivalente por jugador (cuota ÷ jugadores por equipo) | B27: =IF(OR(B5=0,Parametros!F18=0),0,B6/(Parametros!F18/B5)) -> 0
A29: PUNTO DE EQUILIBRIO
A30: Cuota mínima por equipo para cubrir los gastos | B30: =IF(OR(B5=0,(1-B7)*(1-B13-B14)<=0),0,MAX(0,B19-(B9+B10+B11)*(1-B14))/(B5*(1-B7)*(1-B13-B14))) -> 0
A31: Equipos necesarios para cubrir gastos con la cuota ingresada | B31: =IF(OR(B6=0,(1-B7)*(1-B13-B14)<=0),0,ROUNDUP(MAX(0,B19-(B9+B10+B11)*(1-B14))/(B6*(1-B7)*(1-B13-B14)),0)) -> 0
A32: Utilidad objetivo (CLP)
A33: Cuota por equipo para lograr esa utilidad | B33: =IF(OR(B5=0,(1-B7)*(1-B13-B14)<=0),0,MAX(0,B19+B32-(B9+B10+B11)*(1-B14))/(B5*(1-B7)*(1-B13-B14))) -> 0
A35: PLAN DE PAGOS POR EQUIPO
A36: % de reserva al confirmar el cupo
A37: Monto de reserva por equipo | B37: =B6*B36 -> 0
A38: Saldo por equipo | B38: =B6-B37 -> 0
A39: Fecha límite de la reserva
A40: Fecha límite del saldo
A42: UTILIDAD SEGÚN CUOTA Y NÚMERO DE EQUIPOS
A43: Cuota inicial de la tabla (CLP)
A44: Paso entre cuotas (CLP)
A46: Cuota por equipo ↓ / Equipos → | B46: 10 | C46: 15 | D46: 20 | E46: 25 | F46: 30 | G46: 35 | H46: 40
A47: =$B$43+0*$B$44 -> 0 | B47: =B$46*$A47*(1-$B$7)*(1-$B$13-$B$14)+($B$9+$B$10+$B$11)*(1-$B$14)-$B$19 -> 0 | C47: =C$46*$A47*(1-$B$7)*(1-$B$13-$B$14)+($B$9+$B$10+$B$11)*(1-$B$14)-$B$19 -> 0 | D47: =D$46*$A47*(1-$B$7)*(1-$B$13-$B$14)+($B$9+$B$10+$B$11)*(1-$B$14)-$B$19 -> 0 | E47: =E$46*$A47*(1-$B$7)*(1-$B$13-$B$14)+($B$9+$B$10+$B$11)*(1-$B$14)-$B$19 -> 0 | F47: =F$46*$A47*(1-$B$7)*(1-$B$13-$B$14)+($B$9+$B$10+$B$11)*(1-$B$14)-$B$19 -> 0 | G47: =G$46*$A47*(1-$B$7)*(1-$B$13-$B$14)+($B$9+$B$10+$B$11)*(1-$B$14)-$B$19 -> 0 | H47: =H$46*$A47*(1-$B$7)*(1-$B$13-$B$14)+($B$9+$B$10+$B$11)*(1-$B$14)-$B$19 -> 0
...

Sheet Cotizaciones
A1: COTIZACIONES POR PROVEEDOR
A2: Anota tres cotizaciones por rubro y marca la elegida. Imprímela y llévala a terreno; luego pasa el precio a la hoja Gastos.
A3: Rubro | B3: Proveedor 1 | C3: Precio 1 | D3: Proveedor 2 | E3: Precio 2 | F3: Proveedor 3 | G3: Precio 3 | H3: Elegido | I3: Contacto | J3: Notas
A4: Arriendo de canchas
A5: Copas y trofeos
A6: Medallas
A7: Balones
A8: Petos
A9: Conos y equipamiento
A10: Arcos de fútbol 7
A11: Árbitros
A12: Mesa de control / planilleros
A13: Personal organizador
A14: Paramédico / ambulancia
A15: Carpas
... A31: Aseo y basura

Sheet Checklist
A1: CHECKLIST DEL TORNEO
A2: Marca ☐ al cumplir cada tarea. Asigna responsable y fecha.
A3: ☐ | B3: Tarea | C3: Responsable | D3: Fecha límite | E3: Notas
A4: 4 SEMANAS ANTES
A5: ☐ | B5: Confirmar fechas y reservar las canchas por escrito (horarios, montaje y desmontaje)
A6: ☐ | B6: Pedir cotizaciones (hoja Cotizaciones) y definir presupuesto
A7: ☐ | B7: Definir cuota por equipo y plan de pagos
A8: ☐ | B8: Definir cupos por categoría y fecha de cierre de inscripciones
A9: ☐ | B9: Revisar permisos municipales y requisitos del recinto
A10: 3 SEMANAS ANTES
A11: ☐ | B11: Contratar árbitros, mesa de control y paramédico
A12: ☐ | B12: Contratar seguro de accidentes
A13: ☐ | B13: Encargar copas, medallas y trofeos
A14: ☐ | B14: Encargar valla del campeón, banners y banderas
A15: ☐ | B15: Confirmar equipos y recoger nóminas de jugadores
A16: 2 SEMANAS ANTES
A17: ☐ | B17: Recibir las autorizaciones firmadas de apoderados (datos e imagen) de cada club
A18: ☐ | B18: Armar fixture y cronograma de cada cancha (hoja Cronograma)
A19: ☐ | B19: Comprar balones, petos y conos
A20: ☐ | B20: Reservar carpas, sonido, baños y generador
A21: ☐ | B21: Publicar fixture y reglamento en el sitio
A22: 1 SEMANA ANTES
A23: ☐ | B23: Confirmar asistencia del personal y asignar cancha a cada encargado
A24: ☐ | B24: Imprimir fixture, planillas y credenciales
A25: ☐ | B25: Comprar agua y refrigerios
A26: ☐ | B26: Enviar a los clubes horarios, ubicación y reglas de comportamiento
A27: ☐ | B27: Revisar el pronóstico y definir plan de contingencia por clima
A28: DÍA PREVIO
A29: ☐ | B29: Montaje: canchas, arcos, carpas, mesa de control y primeros auxilios
A30: ☐ | B30: Probar sonido y marcador
A31: ☐ | B31: Revisar botiquín y vías de acceso de emergencia
A32: SÁBADO
A33: ☐ | B33: Acreditación de equipos (verificar edades y autorizaciones)
A34: ☐ | B34: Reunión técnica con delegados y árbitros
A35: ☐ | B35: Registrar resultados en el panel admin al terminar cada partido
A36: ☐ | B36: Subir las primeras fotos solo de jugadores con autorización de imagen
A37: DOMINGO
A38: ☐ | B38: Publicar cruces de semifinales y finales
A39: ☐ | B39: Ceremonia de premiación y foto del campeón en la valla
A40: ☐ | B40: Entrega de reconocimientos de participación
...
